<?xml version="1.0" encoding="UTF-8"?>
<robot generator="Robot 3.2.1 (Python 3.6.9 on linux)" generated="20200731 13:30:19.312" rpa="false">
<suite id="s1" name="DDT csv" source="/home/qainfotech/PycharmProjects/robotFrameworkPractice/testSuite/DDT_csv.robot">
<kw name="Open Browser" library="Selenium2Library" type="setup">
<doc>Opens a new browser instance to the optional ``url``.</doc>
<arguments>
<arg>${url}</arg>
<arg>${browser}</arg>
</arguments>
<msg timestamp="20200731 13:30:19.498" level="INFO">Opening browser 'Chrome' to base url 'https://www.saucedemo.com/'.</msg>
<status status="PASS" starttime="20200731 13:30:19.498" endtime="20200731 13:30:23.761"></status>
</kw>
<test id="s1-t1" name="Verify Login Fails With invalid Credentials">
<kw name="Invalid Login Scenarios">
<arguments>
<arg>${username}</arg>
<arg>${password}</arg>
<arg>${error_message}</arg>
</arguments>
<msg timestamp="20200731 13:30:23.765" level="FAIL">Variable '${username}' not found.</msg>
<status status="FAIL" starttime="20200731 13:30:23.764" endtime="20200731 13:30:23.765"></status>
</kw>
<status status="FAIL" starttime="20200731 13:30:23.762" endtime="20200731 13:30:23.765" critical="yes">Variable '${username}' not found.</status>
</test>
<kw name="Close Browser" library="Selenium2Library" type="teardown">
<doc>Closes the current browser.</doc>
<status status="PASS" starttime="20200731 13:30:23.766" endtime="20200731 13:30:23.827"></status>
</kw>
<doc>This is data driven demo testing</doc>
<status status="FAIL" starttime="20200731 13:30:19.314" endtime="20200731 13:30:23.828"></status>
</suite>
<statistics>
<total>
<stat pass="0" fail="1">Critical Tests</stat>
<stat pass="0" fail="1">All Tests</stat>
</total>
<tag>
</tag>
<suite>
<stat pass="0" fail="1" id="s1" name="DDT csv">DDT csv</stat>
</suite>
</statistics>
<errors>
<msg timestamp="20200731 13:30:19.496" level="ERROR">Error in file '/home/qainfotech/PycharmProjects/robotFrameworkPractice/testSuite/DDT_csv.robot' on line 6: Importing test library 'DataDriver' failed: ModuleNotFoundError: No module named 'DataDriver'
Traceback (most recent call last):
  None
PYTHONPATH:
  /usr/lib/python36.zip
  /usr/lib/python3.6
  /usr/lib/python3.6/lib-dynload
  /home/qainfotech/PycharmProjects/APItesting/venv/lib/python3.6/site-packages</msg>
</errors>
</robot>
